# TRACE:
Traceback (most recent call last):
  File "main.py", line 424, in daily
    hour_ago = datetime.timedelta(hours=24)
AttributeError: type object 'datetime.datetime' has no attribute 'timedelta'
