2022-07-31T03:01:08Z Bot is starting up...
2022-07-31T03:01:08Z ERROR TRACE:
Traceback (most recent call last):
  File "main.py", line 601, in <module>
    client.run(os.getenv('TOKEN'))
  File "/opt/virtualenvs/python3/lib/python3.8/site-packages/discord/client.py", line 723, in run
    return future.result()
  File "/usr/lib/python3.8/asyncio/futures.py", line 178, in result
    raise self._exception
  File "/usr/lib/python3.8/asyncio/tasks.py", line 280, in __step
    result = coro.send(None)
  File "/opt/virtualenvs/python3/lib/python3.8/site-packages/discord/client.py", line 702, in runner
    await self.start(*args, **kwargs)
  File "/opt/virtualenvs/python3/lib/python3.8/site-packages/discord/client.py", line 665, in start
    await self.login(*args, bot=bot)
  File "/opt/virtualenvs/python3/lib/python3.8/site-packages/discord/client.py", line 511, in login
    await self.http.static_login(token.strip(), bot=bot)
  File "/opt/virtualenvs/python3/lib/python3.8/site-packages/discord/http.py", line 300, in static_login
    data = await self.request(Route('GET', '/users/@me'))
  File "/opt/virtualenvs/python3/lib/python3.8/site-packages/discord/http.py", line 216, in request
    raise HTTPException(r, data)
discord.errors.HTTPException: 429 Too Many Requests (error code: 0): You are being blocked from accessing our API temporarily due to exceeding our rate limits frequently. Please read our docs at https://discord.com/developers/docs/topics/rate-limits to prevent this moving forward.
# TRACE END

