# TRACE:
Traceback (most recent call last):
  File "main.py", line 218, in message
    f'Woah! It is a slime!  (ﾉ>ω<)ﾉ  Klee has counted {AGE_members[member_id]} slimes for {id_name[member_id]}!'
KeyError: '930545751258447903'
